Workbook

Sheet Detalles - RH
A1: CÁLCULO DETALLADO - RECURSO HUMANO
A3: Equipo
A4: Leidy | B4: Líder de Equipo | I4: Integrante | J4: Rol | K4: Costo por Hora
A5: Alexander | B5: Ingeniero de Requisitos | I5: Leidy Saraguro | J5: Líder de Proyecto | K5: =+B11/160 -> 15.625
A6: Steven | B6: Ingeniero de Requisitos | J6: Ingeniero de Requisitos | K6: =+B12/160 -> 12.5
J7: Diseñador UX/UI | K7: =+B12/160 -> 12.5
A8: Composición del Equipo y Salarios
I9: Integrante | J9: Rol | K9: Costo por Hora
A10: Rol | B10: Salario Mensual (USD) | C10: Salario por Hora (USD) | I10: Alexander Ñacato | J10: Ingeniero de Requisitos | K10: =+B12/160 -> 12.5
A11: Líder de Proyecto | B11: 2500 | C11: =+B11/160 -> 15.625 | J11: Diseñador UX/UI | K11: =+B12/160 -> 12.5
A12: Ingeniero de Requisitos | B12: 2000 | C12: =+B12/160 -> 12.5
A14: Cálculo de Horas y Costos Mensuales | I14: Integrante | J14: Rol | K14: Costo por Hora
I15: Steven Egas | J15: Ingeniero de Requisitos | K15: =+B12/160 -> 12.5
A16: Rol | B16: Cantidad | C16: Horas/Semana | D16: Semanas/Mes | E16: Horas Totales/Mes | F16: Costo por Hora | G16: Costo Total Mensual | J16: Diseñador UX/UI | K16: =+B12/160 -> 12.5
A17: Líder de Equipo | B17: 1 | C17: 9 | D17: 4 | E17: =+B17*C17*D17 -> 36 | F17: =+C11 -> 15.625 | G17: =+E17*F17 -> 562.5
A18: Ingeniero de Requisitos | B18: 2 | C18: 9 | D18: 4 | E18: =+B18*C18*D18 -> 72 | F18: =+C12 -> 12.5 | G18: =+E18*F18 -> 900
E19: =+SUM(E17:E18) -> 108 | G19: =+SUM(G17:G18) -> 1462.5
F20: =+SUM(F17:F18) -> 28.125

Sheet Detalles - Equipos
B1: DEPRECIACIÓN DE EQUIPOS | F1: =+I11+I22 -> 100.48611
A5: COMPUTADORAS
A7: Equipo | B7: Modelo | C7: Valor Inicial | D7: Año de Compra | E7: Antigüedad (meses) | F7: Vida Útil (años) | G7: Vida Útil (meses) | H7: Depreciación Anual | I7: Depreciación Mensual | J7: Depreciacion por hora
A8: PC 1 | B8: ASUS Vivobook X1504ZA | C8: 600 | D8: 2024 | E8: 12 | F8: 3 | G8: 36 | H8: =+C8/F8 -> 200 | I8: =+C8/G8 -> 16.666667 | J8: =+I8/160 -> 0.10416667
A9: PC 2 | B9: ASUS TUF A15 | C9: 1200 | D9: 2023 | E9: 24 | F9: 3 | G9: 36 | H9: =+C9/F9 -> 400 | I9: =+C9/G9 -> 33.333333 | J9: =+I9/160 -> 0.20833333
A10: PC 3 | B10: Acer nitro 5 | C10: 700 | D10: 2022 | E10: 48 | F10: 3 | G10: 36 | H10: =+C10/F10 -> 233.33333 | I10: =+C10/G10 -> 19.444444 | J10: =+I10/160 -> 0.12152778
H11: =+SUM(H8:H10) -> 833.33333 | I11: =+SUM(I8:I10) -> 69.444444 | J11: =+SUM(J8:J10) -> 0.43402778
F12: TOTAL DEPRECIACIÓN COMPUTADORAS
A16: CELULARES
A18: Equipo | B18: Modelo | C18: Valor Inicial | D18: Año de Compra | E18: Antigüedad (meses) | F18: Vida Útil (años) | G18: Vida Útil (meses) | H18: Depreciación Anual | I18: Depreciación Mensual | J18: Depreciacion por hora
A19: Celular 1 | B19: TECNO KJ6 | C19: 200 | D19: 2023 | E19: 24 | F19: 2 | G19: 24 | H19: =+C19/F19 -> 100 | I19: =+C19/G19 -> 8.3333333 | J19: =+I19/160 -> 0.052083333
A20: Celular 2 | B20: IPHONE 12 | C20: 275 | D20: 2022 | E20: 48 | F20: 2 | G20: 24 | H20: =+C20/F20 -> 137.5 | I20: =+C20/G20 -> 11.458333 | J20: =+I20/160 -> 0.071614583
A21: Celular 3 | B21: Xiaomi X5 pro | C21: 270 | D21: 2023 | E21: 12 | F21: 2 | G21: 24 | H21: =+C21/F21 -> 135 | I21: =+C21/G21 -> 11.25 | J21: =+I21/160 -> 0.0703125
H22: =+SUM(H19:H21) -> 372.5 | I22: =+SUM(I19:I21) -> 31.041667 | J22: =+SUM(J19:J21) -> 0.19401042
F23: TOTAL DEPRECIACIÓN CELULARES
B27: Persona 1 | E27: Persona 2 | H27: Persona 3
B28: Depreciación por persona | E28: Depreciación por persona | H28: Depreciación por persona
B29: Depreciación anual | C29: =+H8+H19 -> 300 | E29: Depreciación anual | F29: =+H9+H20 -> 537.5 | H29: Depreciación anual | I29: =+H10+H21 -> 368.33333
B30: Depreciación mensual | C30: =+I8+I19 -> 25 | E30: Depreciación semanal | F30: =+I9+I20 -> 44.791667 | H30: Depreciación semanal | I30: =+I10+I21 -> 30.694444
B31: Depreciación por hora | C31: =+J8+J19 -> 0.15625 | E31: Depreciación por hora | F31: =+J9+J20 -> 0.27994792 | H31: Depreciación por hora | I31: =+J10+J21 -> 0.19184028

Sheet Detalles - Servicios
A1: COSTOS SERVICIOS
A5: Integrante | B5: Rol | C5: N° Personas (Casa) | E5: Horas | F5: horas al mes | G5: Meses semestre | H5: Horas totales trabajadas en el proyecto
A6: Leidy | B6: Líder de Proyecto | C6: 4 | E6: 160 | F6: =+H6/G6 -> 32 | G6: 4.5 | H6: 144
A7: Alex | B7: Ing. Req 1 | C7: 5
A8: Steven | B8: Ing. Req 2 | C8: 4
E10: Plan Internet | F10: Cuota Individual Internet | G10: Cuota por Hora Internet | H10: Cuota mensual Internet | I10: Internet (4.5 Meses)
E11: 35 | F11: =+E11/C6 -> 8.75 | G11: =+F11/$E$6 -> 0.0546875 | H11: =+G11*$F$6 -> 1.75 | I11: =+H11*$G$6 -> 7.875
E12: 32 | F12: =+E12/C7 -> 6.4 | G12: =+F12/$E$6 -> 0.04 | H12: =+G12*$F$6 -> 1.28 | I12: =+H12*$G$6 -> 5.76
E13: 25 | F13: =+E13/C8 -> 6.25 | G13: =+F13/$E$6 -> 0.0390625 | H13: =+G13*$F$6 -> 1.25 | I13: =+H13*$G$6 -> 5.625
G14: =+SUM(G11:G13) -> 0.13375 | I14: =+SUM(I11:I13) -> 19.26
E16: Factura luz | F16: Cuota Individual Luz | G16: Cuota por Hora Luz | H16: Cuota mensual Luz | I16: Luz (4.5 Meses) | M16: TOTAL SERVICIOS MENSUAL | O16: =+I14+I20+I26 -> 41.6475
E17: 30 | F17: =+E17/C6 -> 7.5 | G17: =+F17/$E$6 -> 0.046875 | H17: =+G17*$F$6 -> 1.5 | I17: =+H17*$G$6 -> 6.75
E18: 25 | F18: =+E18/C7 -> 5 | G18: =+F18/$E$6 -> 0.03125 | H18: =+G18*$F$6 -> 1 | I18: =+H18*$G$6 -> 4.5
E19: 15 | F19: =+E19/C8 -> 3.75 | G19: =+F19/$E$6 -> 0.0234375 | H19: =+G19*$F$6 -> 0.75 | I19: =+H19*$G$6 -> 3.375
G20: =+SUM(G17:G19) -> 0.1015625 | I20: =+SUM(I17:I19) -> 14.625
E22: Factura Agua | F22: Cuota Individual agua | G22: Cuota por Hora agua | H22: Cuota mensual Agua | I22: Agua (4.5 meses) | M22: TOTAL SERVICIOS POR HORA | O22: =+G14+G20+G26 -> 0.28921875
E23: 11.25 | F23: =+E23/C6 -> 2.8125 | G23: =+F23/$E$6 -> 0.017578125 | H23: =+G23*$F$6 -> 0.5625 | I23: =+H23*$G$6 -> 2.53125
E24: 12 | F24: =+E24/C7 -> 2.4 | G24: =+F24/$E$6 -> 0.015 | H24: =+G24*$F$6 -> 0.48 | I24: =+H24*$G$6 -> 2.16
E25: 13.65 | F25: =+E25/C8 -> 3.4125 | G25: =+F25/$E$6 -> 0.021328125 | H25: =+G25*$F$6 -> 0.6825 | I25: =+H25*$G$6 -> 3.07125
G26: =+SUM(G23:G25) -> 0.05390625 | I26: =+SUM(I23:I25) -> 7.7625

Sheet Planificacion_HORAS
B3: Nombre de tarea | C3: Duracion Horas | D3: Comienzo | E3: Fin | F3: Predecesoras | G3: Nombres de los recursos
B4: Fase 1 – Elicitación de Requisitos | C4: =+C5+C12 -> 37
B5: TE1 - ENTREVISTA | C5: =+SUM(C6:C11) -> 15 | D5: mar 18/11/25 | E5: lun 24/11/25
B6: Planeación de tecnica Entrevista | C6: 2 | D6: mar 18/11/25 | E6: mar 18/11/25 | G6: Leidy (Lider)
B7: Preparación del banco de preguntas | C7: 3 | D7: mié 19/11/25 | E7: mié 19/11/25 | F7: 3 | G7: G1
B8: Contacto y agendamiento con cliente | C8: 3 | D8: jue 20/11/25 | E8: jue 20/11/25 | F8: 3 | G8: Leidy (Lider)
B9: Aplicación de entrevista | C9: 1 | D9: sáb 22/11/25 | E9: sáb 22/11/25 | F9: 4,5 | G9: Steven
B10: Elaboración de minuta | C10: 4 | D10: dom 23/11/25 | E10: dom 23/11/25 | F10: 6 | G10: Alex
B11: Revisión de la minuta | C11: 2 | D11: lun 24/11/25 | E11: lun 24/11/25 | F11: 7 | G11: Leidy (Lider)
B12: TE2 - Historias de usuario | C12: =+SUM(C13:C20) -> 22 | D12: jue 04/12/25 | E12: dom 14/12/25
B13: Planificación de la técnica Historias de Usuario | C13: 2 | D13: jue 04/12/25 | E13: jue 04/12/25 | F13: 8 | G13: Leidy (Lider)
B14: Contacto y coordinación con la secretaria | C14: 1 | D14: vie 05/12/25 | E14: vie 05/12/25 | F14: 10 | G14: Leidy (Lider)
B15: Definición de secciones y preguntas guía | C15: 3 | D15: lun 08/12/25 | E15: lun 08/12/25 | F15: 10 | G15: Leidy (Lider),Alex
B16: Preparación del formato de Historias de Usuario | C16: 2 | D16: mar 09/12/25 | E16: mar 09/12/25 | F16: 12 | G16: Alex
B17: Aplicación de Historias de Usuario (sesión guiada) | C17: 2 | D17: jue 11/12/25 | E17: jue 11/12/25 | F17: 11,13 | G17: Leidy (Lider)
B18: Organización de información obtenida | C18: 3 | D18: vie 12/12/25 | E18: vie 12/12/25 | F18: 14 | G18: Steven
B19: Redacción del documento de Historias de Usuario | C19: 6 | D19: sáb 13/12/25 | E19: sáb 13/12/25 | F19: 15 | G19: G1
B20: Revisión final de Historias de Usuario | C20: 3 | D20: dom 14/12/25 | E20: dom 14/12/25 | F20: 16 | G20: G1
B21: Fase 2 – ANÁLISIS | C21: =+C22+C28+C35 -> 40 | D21: lun 05/01/26 | E21: mié 14/01/26
B22: TA1. Arbol de problemas | C22: =+SUM(C23:C27) -> 16 | D22: lun 05/01/26 | E22: dom 11/01/26
B23: Identificación del problema central | C23: 2 | D23: lun 05/01/26 | E23: lun 05/01/26 | F23: 17 | G23: G1
B24: Identificación de causas | C24: 4 | D24: mar 06/01/26 | E24: mar 06/01/26 | F24: 20 | G24: G1
B25: Identificación de efectos | C25: 4 | D25: mié 07/01/26 | E25: mié 07/01/26 | F25: 21 | G25: G1
B26: Construcción gráfica del árbol | C26: 4 | D26: jue 08/01/26 | E26: jue 08/01/26 | F26: 22 | G26: Leidy (Lider)
B27: Revisión y validación del árbol | C27: 2 | D27: dom 11/01/26 | E27: dom 11/01/26 | F27: 23 | G27: G1
B28: TA1. Casos de Uso | C28: =+SUM(C29:C34) -> 16 | D28: mar 06/01/26 | E28: dom 11/01/26
B29: Identificación de actores | C29: 2 | D29: mar 06/01/26 | E29: mar 06/01/26 | F29: 24 | G29: Alex
B30: Identificación de casos de uso | C30: 4 | D30: mié 07/01/26 | E30: mié 07/01/26 | F30: 26 | G30: Alex
B31: Elaboración CU situación actual | C31: 4 | D31: jue 08/01/26 | E31: jue 08/01/26 | F31: 27 | G31: Alex
B32: Modelado CU Propuesta 1 | C32: 2 | D32: vie 09/01/26 | E32: vie 09/01/26 | F32: 28 | G32: Steven
B33: Modelado CU Propuesta 2 | C33: 2 | D33: sáb 10/01/26 | E33: sáb 10/01/26 | F33: 29 | G33: Alex
B34: Revisión de diagramas CU | C34: 2 | D34: dom 11/01/26 | E34: dom 11/01/26 | F34: 30 | G34: G1
B35: TA2. Modelo Conceptual | C35: =+SUM(C36:C39) -> 8 | D35: lun 12/01/26 | E35: mié 14/01/26
B36: Identificación de entidades | C36: 2 | D36: lun 12/01/26 | E36: lun 12/01/26 | F36: 31 | G36: Leidy (Lider)
B37: Definición de atributos y relaciones | C37: 3 | D37: mar 13/01/26 | E37: mar 13/01/26 | F37: 33 | G37: Leidy (Lider)
B38: Construcción del modelo conceptual | C38: 2 | D38: mié 14/01/26 | E38: mié 14/01/26 | F38: 34 | G38: Leidy (Lider)
B39: Revisión y ajustes finales | C39: 1 | D39: mié 14/01/26 | E39: mié 14/01/26 | F39: 35 | G39: G1
B40: Fase 3.- Especificacion | C40: =+C41+C46 -> 35 | D40: jue 15/01/26 | E40: dom 18/01/26
B41: Costo por caso de uso propuesta 1 | C41: =+SUM(C42:C45) -> 18 | D41: jue 15/01/26 | E41: vie 16/01/26 | I41: HORAS TOTALES P1 | J41: {=+SUM(C32+C42:C45)} -> 26
B42: CU-Inicicar sesion | C42: 4 | D42: jue 15/01/26 | E42: jue 15/01/26 | F42: 36 | G42: Steven
...

Sheet CU (2)
B5: Costo Total | D5: Mano De obra+ Equipos+ Servicios | E5: =+SUM(Proyección!B5:B7) -> 1604.6336
B9: Costo por caso de uso propuesta 2
B12: Costo por hora | D12: Costo_Total/Horas_Totales | E12: =+E5/Planificacion_HORAS!J46 -> 200.5792
B14: Costo por caso uso | D14: Costo_Total/Numero_de_CU | E14: =+E5/Planificacion_HORAS!J48 -> 267.43894

Sheet Proyección
A1: PROYECCIÓN DE COSTOS - DIFERENTES PERÍODOS
A4: Categoría de Gasto | B4: Costo Mensual (USD) | C4: Porcentaje del Total
A5: Recurso Humano | B5: ='Detalles - RH'!G19 -> 1462.5 | C5: =+B5/B8 -> 0.91142301
A6: Depreciación de Equipos (Computadoras + Celulares) | B6: ='Detalles - Equipos'!F1 -> 100.48611 | C6: =+B6/B8 -> 0.062622464
A7: Servicios e Infraestructura | B7: =+'Detalles - Servicios'!O16 -> 41.6475 | C7: =+B7/B8 -> 0.025954523
A8: COSTO TOTAL MENSUAL DEL PROYECTO | B8: =+SUM(B5:B7) -> 1604.6336
A11: Concepto | B11: Costo Mensual | C11: 1 Mes | D11: 3 Meses | E11: 6 Meses | F11: 12 Meses | G11: 18 Meses | H11: 24 Meses
A12: Recurso Humano | B12: ='Detalles - RH'!G19 -> 1462.5 | C12: =+B12*1 -> 1462.5 | D12: =+B12*3 -> 4387.5 | E12: =+B12*6 -> 8775 | F12: =+B12*12 -> 17550 | G12: =+B12*18 -> 26325 | H12: =+B12*24 -> 35100
A13: Depreciación Equipos | B13: ='Detalles - Equipos'!F1 -> 100.48611 | C13: =+B13*1 -> 100.48611 | D13: =+B13*3 -> 301.45833 | E13: =+B13*6 -> 602.91667 | F13: =+B13*12 -> 1205.8333 | G13: =+B13*18 -> 1808.75 | H13: =+B13*24 -> 2411.6667
A14: Servicios e Infraestructura | B14: =+'Detalles - Servicios'!O16 -> 41.6475 | C14: =+B14*1 -> 41.6475 | D14: =+B14*3 -> 124.9425 | E14: =+B14*6 -> 249.885 | F14: =+B14*12 -> 499.77 | G14: =+B14*18 -> 749.655 | H14: =+B14*24 -> 999.54
A17: Levantamiento de requisitos (20%) | B17: =+'Estimacion_Propuesta 2'!J67 -> 3045.5391
A18: Elaboracion del proyecto (80%) | B18: =+(0.8*B17)/0.2 -> 12182.156
A19: Presupuesto para contingencias (10%) | B19: =+(0.1*B17)/0.2 -> 1522.7696
A20: TOTAL DEL PROYECTO | B20: =+SUM(B17:B19) -> 16750.465

Sheet Estimacion_Propuesta 2
B3: Fase 1 – Elicitación de Requisitos | C3: =+C5+C12 -> 37
B4: Nombre de tarea | C4: Duracion Horas | D4: Comienzo | E4: Fin | F4: Predecesoras | G4: Nombres de los recursos | H4: Rol | I4: Costo RH | J4: Costo Equipos | K4: Costo Servicios | L4: Subtotal | O4: TOTAL SERVICIOS POR HORA | P4: =+'Detalles - Servicios'!O22 -> 0.28921875
B5: TE1 - ENTREVISTA | C5: =+SUM(C6:C11) -> 15 | D5: mar 18/11/25 | E5: lun 24/11/25
B6: Planeación de tecnica Entrevista | C6: 2 | D6: mar 18/11/25 | E6: mar 18/11/25 | G6: Leidy (Lider) | H6: Líder de Proyecto + Ingeniero de Requisitos | I6: =+C6*($Q$11+$Q$12) -> 56.25 | J6: =3*C6*$Q$6 -> 0.9375 | K6: =3*C6*$P$4 -> 1.7353125 | L6: =+SUM(I6:K6) -> 58.922812 | O6: TOTAL EQUIPOS POR HORA | P6: Persona 1 | Q6: =+'Detalles - Equipos'!C31 -> 0.15625
B7: Preparación del banco de preguntas | C7: 3 | D7: mié 19/11/25 | E7: mié 19/11/25 | F7: 3 | G7: G1 | H7: Ingeniero de Requisitos | I7: =+C7*($Q$12+$Q$16+$Q$21) -> 112.5 | J7: =3*C7*($Q$6+$Q$7+$Q$8) -> 5.6523438 | K7: =3*C7*$P$4 -> 2.6029688 | L7: =+SUM(I7:K7) -> 120.75531 | P7: Persona 2 | Q7: =+'Detalles - Equipos'!F31 -> 0.27994792
B8: Contacto y agendamiento con cliente | C8: 3 | D8: jue 20/11/25 | E8: jue 20/11/25 | F8: 3 | G8: Leidy (Lider) | H8: Líder de Proyecto | I8: =+C8*($Q$11) -> 46.875 | J8: =3*C8*$Q$6 -> 1.40625 | K8: =3*C8*$P$4 -> 2.6029688 | L8: =+SUM(I8:K8) -> 50.884219 | P8: Persona 3 | Q8: =+'Detalles - Equipos'!I31 -> 0.19184028
B9: Aplicación de entrevista | C9: 1 | D9: sáb 22/11/25 | E9: sáb 22/11/25 | F9: 4,5 | G9: Steven | H9: Ingeniero de Requisitos | I9: =+C9*($Q$21) -> 12.5 | J9: =3*C9*$Q$8 -> 0.57552083 | K9: =3*C9*$P$4 -> 0.86765625 | L9: =+SUM(I9:K9) -> 13.943177
B10: Elaboración de minuta | C10: 4 | D10: dom 23/11/25 | E10: dom 23/11/25 | F10: 6 | G10: Alex | H10: Ingeniero de Requisitos | I10: =+C10*($Q$16) -> 50 | J10: =3*C10*$Q$7 -> 3.359375 | K10: =3*C10*$P$4 -> 3.470625 | L10: =+SUM(I10:K10) -> 56.83 | O10: Integrante | P10: Rol | Q10: Costo por Hora
B11: Revisión de la minuta | C11: 2 | D11: lun 24/11/25 | E11: lun 24/11/25 | F11: 7 | G11: Leidy (Lider) | H11: Líder de Proyecto + Ingeniero de Requisitos | I11: =+C11*(Q11+Q12) -> 56.25 | J11: =3*C11*$Q$6 -> 0.9375 | K11: =3*C11*$P$4 -> 1.7353125 | L11: =+SUM(I11:K11) -> 58.922812 | O11: Leidy Saraguro | P11: Líder de Proyecto | Q11: =+'Detalles - RH'!K5 -> 15.625
B12: TE2 - Historias de usuario | C12: =+SUM(C13:C20) -> 22 | D12: jue 04/12/25 | E12: dom 14/12/25 | P12: Ingeniero de Requisitos | Q12: =+'Detalles - RH'!K6 -> 12.5
B13: Planificación de la técnica Historias de Usuario | C13: 2 | D13: jue 04/12/25 | E13: jue 04/12/25 | F13: 8 | G13: Leidy (Lider) | H13: Líder de Proyecto + Ingeniero de Requisitos | I13: =+C13*($Q$11+$Q$12) -> 56.25 | J13: =3*C13*$Q$6 -> 0.9375 | K13: =3*C13*$P$4 -> 1.7353125 | L13: =+SUM(I13:K13) -> 58.922812 | P13: Diseñador UX/UI | Q13: =+'Detalles - RH'!K7 -> 12.5
B14: Contacto y coordinación con la secretaria | C14: 1 | D14: vie 05/12/25 | E14: vie 05/12/25 | F14: 10 | G14: Leidy (Lider) | H14: Líder de Proyecto | I14: =+C14*($Q$11) -> 15.625 | J14: =3*C14*$Q$6 -> 0.46875 | K14: =3*C14*$P$4 -> 0.86765625 | L14: =+SUM(I14:K14) -> 16.961406
B15: Definición de secciones y preguntas guía | C15: 3 | D15: lun 08/12/25 | E15: lun 08/12/25 | F15: 10 | G15: Leidy (Lider),Alex | H15: Ingeniero de Requisitos | I15: =+C15*(Q12+Q16) -> 75 | J15: =3*C15*(Q6+Q7) -> 3.9257812 | K15: =3*C15*$P$4 -> 2.6029688 | L15: =+SUM(I15:K15) -> 81.52875 | O15: Integrante | P15: Rol | Q15: Costo por Hora
B16: Preparación del formato de Historias de Usuario | C16: 2 | D16: mar 09/12/25 | E16: mar 09/12/25 | F16: 12 | G16: Alex | H16: Ingeniero de Requisitos | I16: =+C16*($Q$16) -> 25 | J16: =3*C16*$Q$7 -> 1.6796875 | K16: =3*C16*$P$4 -> 1.7353125 | L16: =+SUM(I16:K16) -> 28.415 | O16: Alexander Ñacato | P16: Ingeniero de Requisitos | Q16: =+'Detalles - RH'!K10 -> 12.5
B17: Aplicación de Historias de Usuario (sesión guiada) | C17: 2 | D17: jue 11/12/25 | E17: jue 11/12/25 | F17: 11,13 | G17: Leidy (Lider) | H17: Ingeniero de Requisitos | I17: =+C17*(Q22+Q23) -> 25 | J17: =3*C17*$Q$6 -> 0.9375 | K17: =3*C17*$P$4 -> 1.7353125 | L17: =+SUM(I17:K17) -> 27.672812 | P17: Diseñador UX/UI | Q17: =+'Detalles - RH'!K11 -> 12.5
B18: Organización de información obtenida | C18: 3 | D18: vie 12/12/25 | E18: vie 12/12/25 | F18: 14 | G18: Steven | H18: Ingeniero de Requisitos | I18: =+C18*($Q$21) -> 37.5 | J18: =3*C18*$Q$8 -> 1.7265625 | K18: =3*C18*$P$4 -> 2.6029688 | L18: =+SUM(I18:K18) -> 41.829531
B19: Redacción del documento de Historias de Usuario | C19: 6 | D19: sáb 13/12/25 | E19: sáb 13/12/25 | F19: 15 | G19: G1 | H19: Ingeniero de Requisitos | I19: =+C19*($Q$12+$Q$16+$Q$21) -> 225 | J19: =3*C19*($Q$6+$Q$7+$Q$8) -> 11.304688 | K19: =3*C19*$P$4 -> 5.2059375 | L19: =+SUM(I19:K19) -> 241.51063
B20: Revisión final de Historias de Usuario | C20: 3 | D20: dom 14/12/25 | E20: dom 14/12/25 | F20: 16 | G20: G1 | H20: Líder de Proyecto + Ingeniero de Requisitos | I20: =+C20*(Q25+Q26) -> 0 | J20: =3*C20*($Q$6+$Q$7+$Q$8) -> 5.6523438 | K20: =3*C20*$P$4 -> 2.6029688 | L20: =+SUM(I20:K20) -> 8.2553125 | O20: Integrante | P20: Rol | Q20: Costo por Hora
O21: Steven Egas | P21: Ingeniero de Requisitos | Q21: =+'Detalles - RH'!K15 -> 12.5
B22: Fase 2 – ANÁLISIS | C22: =+C24+C30+C36 -> 38 | D22: lun 05/01/26 | E22: mié 14/01/26 | P22: Diseñador UX/UI | Q22: =+'Detalles - RH'!K16 -> 12.5
B23: Nombre de tarea | C23: Duracion Horas | D23: Comienzo | E23: Fin | F23: Predecesoras | G23: Nombres de los recursos | H23: Rol | I23: Costo RH | J23: Costo Equipos | K23: Costo Servicios | L23: Subtotal
B24: TA1. Arbol de problemas | C24: =+SUM(C25:C29) -> 16 | D24: lun 05/01/26 | E24: dom 11/01/26
B25: Identificación del problema central | C25: 2 | D25: lun 05/01/26 | E25: lun 05/01/26 | F25: 17 | G25: G1 | H25: Ingeniero de Requisitos | I25: =+C25*($Q$12+$Q$16+$Q$21) -> 75 | J25: =3*C25*($Q$6+$Q$7+$Q$8) -> 3.7682292 | K25: =3*C25*$P$4 -> 1.7353125 | L25: =+SUM(I25:K25) -> 80.503542
B26: Identificación de causas | C26: 4 | D26: mar 06/01/26 | E26: mar 06/01/26 | F26: 20 | G26: G1 | H26: Ingeniero de Requisitos | I26: =+C26*($Q$12+$Q$16+$Q$21) -> 150 | J26: =3*C26*($Q$6+$Q$7+$Q$8) -> 7.5364583 | K26: =3*C26*$P$4 -> 3.470625 | L26: =+SUM(I26:K26) -> 161.00708
B27: Identificación de efectos | C27: 4 | D27: mié 07/01/26 | E27: mié 07/01/26 | F27: 21 | G27: G1 | H27: Ingeniero de Requisitos | I27: =+C27*($Q$12+$Q$16+$Q$21) -> 150 | J27: =3*C27*($Q$6+$Q$7+$Q$8) -> 7.5364583 | K27: =3*C27*$P$4 -> 3.470625 | L27: =+SUM(I27:K27) -> 161.00708
B28: Construcción gráfica del árbol | C28: 4 | D28: jue 08/01/26 | E28: jue 08/01/26 | F28: 22 | G28: Leidy (Lider) | H28: Ingeniero de Requisitos + Diseñador UX/UI | I28: =+C28*(Q11+Q13) -> 112.5 | J28: =3*C28*$Q$6 -> 1.875 | K28: =3*C28*$P$4 -> 3.470625 | L28: =+SUM(I28:K28) -> 117.84562
B29: Revisión y validación del árbol | C29: 2 | D29: dom 11/01/26 | E29: dom 11/01/26 | F29: 23 | G29: G1 | H29: Líder de Proyecto + Ingeniero de Requisitos | I29: =+C29*($Q$11+$Q$12+$Q$16+$Q$21) -> 106.25 | J29: =3*C29*($Q$6+$Q$7+$Q$8) -> 3.7682292 | K29: =3*C29*$P$4 -> 1.7353125 | L29: =+SUM(I29:K29) -> 111.75354
B30: TA1. Casos de Uso | C30: =+SUM(C31:C35) -> 14 | D30: mar 06/01/26 | E30: dom 11/01/26
B31: Identificación de actores | C31: 2 | D31: mar 06/01/26 | E31: mar 06/01/26 | F31: 24 | G31: Alex | H31: Ingeniero de Requisitos | I31: =+C31*($Q$16) -> 25 | J31: =3*C31*$Q$7 -> 1.6796875 | K31: =3*C31*$P$4 -> 1.7353125 | L31: =+SUM(I31:K31) -> 28.415
B32: Identificación de casos de uso | C32: 4 | D32: mié 07/01/26 | E32: mié 07/01/26 | F32: 26 | G32: Alex | H32: Ingeniero de Requisitos | I32: =+C32*($Q$16) -> 50 | J32: =3*C32*$Q$7 -> 3.359375 | K32: =3*C32*$P$4 -> 3.470625 | L32: =+SUM(I32:K32) -> 56.83
B33: Elaboración CU situación actual | C33: 4 | D33: jue 08/01/26 | E33: jue 08/01/26 | F33: 27 | G33: Alex | H33: Ingeniero de Requisitos | I33: =+C33*($Q$16) -> 50 | J33: =3*C33*$Q$7 -> 3.359375 | K33: =3*C33*$P$4 -> 3.470625 | L33: =+SUM(I33:K33) -> 56.83
B34: Modelado CU Propuesta 2 | C34: 2 | D34: sáb 10/01/26 | E34: sáb 10/01/26 | F34: 29 | G34: Alex | H34: Ingeniero de Requisitos | I34: =+C34*($Q$16) -> 25 | J34: =3*C34*$Q$7 -> 1.6796875 | K34: =3*C34*$P$4 -> 1.7353125 | L34: =+SUM(I34:K34) -> 28.415
B35: Revisión de diagramas CU | C35: 2 | D35: dom 11/01/26 | E35: dom 11/01/26 | F35: 30 | G35: G1 | H35: Líder de Proyecto + Ingeniero de Requisitos | I35: =+C35*($Q$11+$Q$12+$Q$16+$Q$21) -> 106.25 | J35: =3*C35*($Q$6+$Q$7+$Q$8) -> 3.7682292 | K35: =3*C35*$P$4 -> 1.7353125 | L35: =+SUM(I35:K35) -> 111.75354
B36: TA2. Modelo Conceptual | C36: =+SUM(C37:C40) -> 8 | D36: lun 12/01/26 | E36: mié 14/01/26
B37: Identificación de entidades | C37: 2 | D37: lun 12/01/26 | E37: lun 12/01/26 | F37: 31 | G37: Leidy (Lider) | H37: Ingeniero de Requisitos | I37: =+C37*$Q$11 -> 31.25 | J37: =3*C37*$Q$6 -> 0.9375 | K37: =3*C37*$P$4 -> 1.7353125 | L37: =+SUM(I37:K37) -> 33.922812
B38: Definición de atributos y relaciones | C38: 3 | D38: mar 13/01/26 | E38: mar 13/01/26 | F38: 33 | G38: Leidy (Lider) | H38: Ingeniero de Requisitos | I38: =+C38*$Q$11 -> 46.875 | J38: =3*C38*$Q$6 -> 1.40625 | K38: =3*C38*$P$4 -> 2.6029688 | L38: =+SUM(I38:K38) -> 50.884219
B39: Construcción del modelo conceptual | C39: 2 | D39: mié 14/01/26 | E39: mié 14/01/26 | F39: 34 | G39: Leidy (Lider) | H39: Ingeniero de Requisitos | I39: =+C39*$Q$11 -> 31.25 | J39: =3*C39*$Q$6 -> 0.9375 | K39: =3*C39*$P$4 -> 1.7353125 | L39: =+SUM(I39:K39) -> 33.922812
B40: Revisión y ajustes finales | C40: 1 | D40: mié 14/01/26 | E40: mié 14/01/26 | F40: 35 | G40: G1 | H40: Líder de Proyecto + Ingeniero de Requisitos | I40: =+C40*($Q$11+$Q$12+$Q$16+$Q$21) -> 53.125 | J40: =3*C40*($Q$6+$Q$7+$Q$8) -> 1.8841146 | K40: =3*C40*$P$4 -> 0.86765625 | L40: =+SUM(I40:K40) -> 55.876771
B42: Fase 3.- Especificacion | C42: =+C44 -> 17 | D42: jue 15/01/26 | E42: dom 18/01/26
B43: Nombre de tarea | C43: Duracion Horas | D43: Comienzo | E43: Fin | F43: Predecesoras | G43: Nombres de los recursos | H43: Rol | I43: Costo RH | J43: Costo Equipos | K43: Costo Servicios | L43: Subtotal
...
